Workbook

Sheet Checklist Production
A1: 🚀 THE PROMPT STUDIO — Plan de mise en production
A2: Cochez chaque étape au fur et à mesure. ✅=Fait ⬜=À faire ⏳=En cours ❌=Bloqué
A3: Progression : | C3: =CONCATENATE(COUNTIF(A5:A200,"✅")," / ",COUNTA(C5:C200)," tâches complétées (",ROUND(COUNTIF(A5:A200,"✅")/MAX(COUNTA(C5:C200),1)*100,0),"%)") -> 25 / 69 tâches complétées (36%)
A4: ✓ | B4: Priorité | C4: Tâche | D4: Détails / Action | E4: Responsable | F4: Deadline | G4: Notes
A5: 🔑 1. SECRETS & SÉCURITÉ
A6: ✅ | B6: 🔴 Critique | C6: Régénérer la clé Supabase Service Key | D6: Supabase → Settings → API → service_role key | E6: Mathieu | F6: J-1
A7: ✅ | B7: 🔴 Critique | C7: Régénérer la clé Anthropic API Key | D7: console.anthropic.com → API Keys → Create new | E7: Mathieu | F7: J-1
A8: ✅ | B8: 🔴 Critique | C8: Régénérer le secret Lemon Squeezy Webhook | D8: Lemon Squeezy → Settings → Webhooks | E8: Mathieu | F8: J-1
A9: ✅ | B9: 🔴 Critique | C9: Vérifier que .env n'est PAS dans git | D9: git log --all -- .env (doit être vide) | E9: Mathieu | F9: J-1
A10: ⚙️ 2. VARIABLES D'ENVIRONNEMENT NETLIFY
A11: ✅ | B11: 🔴 Critique | C11: Configurer SUPABASE_URL | D11: Netlify → Site → Environment Variables | E11: Mathieu | F11: J-1
A12: ✅ | B12: 🔴 Critique | C12: Configurer SUPABASE_SERVICE_KEY | D12: Nouvelle clé générée à l'étape 1 | E12: Mathieu | F12: J-1
A13: ✅ | B13: 🔴 Critique | C13: Configurer ANTHROPIC_API_KEY | D13: Nouvelle clé générée à l'étape 1 | E13: Mathieu | F13: J-1
A14: ✅ | B14: 🟠 Important | C14: Configurer CLAUDE_MODEL | D14: claude-haiku-4-5-20251001 | E14: Mathieu | F14: J-1
A15: ✅ | B15: 🟠 Important | C15: Configurer DEFAULT_MAX_TOKENS | D15: 800 | E15: Mathieu | F15: J-1
A16: ✅ | B16: 🔴 Critique | C16: Configurer LS_WEBHOOK_SECRET | D16: Nouveau secret Lemon Squeezy | E16: Mathieu | F16: J-1
A17: ✅ | B17: 🟠 Important | C17: Configurer ALLOWED_ORIGIN | D17: https://theprompt.studio | E17: Mathieu | F17: J-1
A18: 🗄️ 3. BASE DE DONNÉES SUPABASE
A19: ✅ | B19: 🔴 Critique | C19: Exécuter sql/SAFE-full-migration.sql | D19: SQL Editor Supabase — crée toutes les tables, RLS, RPCs | E19: Mathieu | F19: J-1
A20: ✅ | B20: 🔴 Critique | C20: Exécuter sql/analytics-complete.sql | D20: Tables events, pricing, feature_adoptions + 10 vues admin | E20: Mathieu | F20: J-1
A21: ✅ | B21: 🔴 Critique | C21: Exécuter sql/update-all-tool-schemas.sql | D21: Injecte les input_schema des 100 outils | E21: Mathieu | F21: J-1
A22: ✅ | B22: 🟠 Important | C22: Vérifier RLS activé sur toutes les tables | D22: Supabase → Authentication → Policies | E22: Mathieu | F22: J-1
A23: ❌ | B23: 🟠 Important | C23: Activer les backups automatiques | D23: Supabase → Settings → Database → Backups | E23: Mathieu | F23: J-1
A24: 🔐 4. AUTHENTIFICATION SUPABASE
A25: ✅ | B25: 🔴 Critique | C25: Configurer Site URL | D25: Auth → URL Configuration → https://theprompt.studio | E25: Mathieu | F25: J-1
A26: ✅ | B26: 🔴 Critique | C26: Configurer Redirect URLs | D26: https://theprompt.studio/** | E26: Mathieu | F26: J-1
A27: ❌ | B27: 🟠 Important | C27: Personnaliser le template Magic Link (optionnel si auth email/mdp) | D27: Auth → Email Templates. Non requis si auth classique email + mot de passe | E27: Mathieu | F27: Semaine 1 | G27: Magic link = méthode alternative. Pas nécessaire pour auth classique.
A28: ✅ | B28: 🟠 Important | C28: Personnaliser le template Confirmation (requis) | D28: Auth → Email Templates → email envoyé après signUp pour vérifier l'adresse | E28: Mathieu | F28: Semaine 1 | G28: Utilisé par auth email/mdp pour confirmer l'email. À garder activé.
A29: ⬜ | B29: 🟡 Moyen | C29: Configurer Google OAuth | D29: Permet "Se connecter avec Google" en plus de email/mdp | E29: Mathieu | F29: Mois 1 | G29: 5 sous-étapes ci-dessous
A30: ✅ | B30: 🟡 Moyen | C30: ↳ 4a. Créer projet Google Cloud | D30: console.cloud.google.com → New Project → "The Prompt Studio" | E30: Mathieu | F30: Mois 1
A31: ⬜ | B31: 🟡 Moyen | C31: ↳ 4b. Configurer OAuth Consent Screen | D31: APIs & Services → OAuth consent → External → app name + domaine autorisé theprompt.studio | E31: Mathieu | F31: Mois 1 | G31: Scopes par défaut: email, profile, openid
A32: ⬜ | B32: 🟡 Moyen | C32: ↳ 4c. Créer OAuth 2.0 Client ID | D32: Credentials → Create → Web app → Redirect URI: <ref>.supabase.co/auth/v1/callback | E32: Mathieu | F32: Mois 1 | G32: Ajouter aussi localhost pour le dev
A33: ⬜ | B33: 🟡 Moyen | C33: ↳ 4d. Activer Google dans Supabase | D33: Supabase → Auth → Providers → Google → ON → coller Client ID + Secret | E33: Mathieu | F33: Mois 1
A34: ⬜ | B34: 🟡 Moyen | C34: ↳ 4e. Ajouter bouton "Sign in with Google" dans le frontend | D34: ps-auth.js → supabase.auth.signInWithOAuth({ provider: "google" }) | E34: Mathieu | F34: Mois 1 | G34: redirectTo: /dashboard.html
A35: 🌐 5. DOMAINE & DNS
A36: ✅ | B36: 🔴 Critique | C36: Ajouter domaine theprompt.studio sur Netlify | D36: Netlify → Domain management → Add domain | E36: Mathieu | F36: J-1
A37: ✅ | B37: 🔴 Critique | C37: Configurer DNS (A record + CNAME www) | D37: A @ → 75.2.60.5 / CNAME www → theprompt.studio | E37: Mathieu | F37: J-1
A38: ✅ | B38: 🔴 Critique | C38: Vérifier HTTPS automatique actif | D38: Netlify → Domain → HTTPS (Let's Encrypt) | E38: Mathieu | F38: J-1
A39: 💳 6. PAIEMENTS LEMON SQUEEZY
A40: ⬜ | B40: 🔴 Critique | C40: Créer les produits Immobilier (4 tiers × 2 périodes) | D40: Starter/Pro/Gold/Team × Monthly/Yearly = 8 produits | E40: Mathieu | F40: J-1
...

Sheet Résumé
A1: 📊 Résumé de progression
A2: Catégorie | B2: ✅ Fait | C2: ⬜ À faire | D2: ⏳ En cours | E2: ❌ Bloqué
A3: Secrets & Sécurité | B3: =COUNTIF('Checklist Production'!A6:A9,"✅") -> 4 | C3: =COUNTIF('Checklist Production'!A6:A9,"⬜") -> 0 | D3: =COUNTIF('Checklist Production'!A6:A9,"⏳") -> 0 | E3: =COUNTIF('Checklist Production'!A6:A9,"❌") -> 0
A4: Variables Netlify | B4: =COUNTIF('Checklist Production'!A11:A17,"✅") -> 7 | C4: =COUNTIF('Checklist Production'!A11:A17,"⬜") -> 0 | D4: =COUNTIF('Checklist Production'!A11:A17,"⏳") -> 0 | E4: =COUNTIF('Checklist Production'!A11:A17,"❌") -> 0
A5: Base de données | B5: =COUNTIF('Checklist Production'!A19:A23,"✅") -> 4 | C5: =COUNTIF('Checklist Production'!A19:A23,"⬜") -> 0 | D5: =COUNTIF('Checklist Production'!A19:A23,"⏳") -> 0 | E5: =COUNTIF('Checklist Production'!A19:A23,"❌") -> 1
A6: Authentification | B6: =COUNTIF('Checklist Production'!A25:A29,"✅") -> 3 | C6: =COUNTIF('Checklist Production'!A25:A29,"⬜") -> 1 | D6: =COUNTIF('Checklist Production'!A25:A29,"⏳") -> 0 | E6: =COUNTIF('Checklist Production'!A25:A29,"❌") -> 1
A7: Domaine & DNS | B7: =COUNTIF('Checklist Production'!A31:A33,"✅") -> 0 | C7: =COUNTIF('Checklist Production'!A31:A33,"⬜") -> 3 | D7: =COUNTIF('Checklist Production'!A31:A33,"⏳") -> 0 | E7: =COUNTIF('Checklist Production'!A31:A33,"❌") -> 0
A8: Paiements | B8: =COUNTIF('Checklist Production'!A35:A42,"✅") -> 3 | C8: =COUNTIF('Checklist Production'!A35:A42,"⬜") -> 3 | D8: =COUNTIF('Checklist Production'!A35:A42,"⏳") -> 0 | E8: =COUNTIF('Checklist Production'!A35:A42,"❌") -> 0
A9: Emails | B9: =COUNTIF('Checklist Production'!A44:A48,"✅") -> 0 | C9: =COUNTIF('Checklist Production'!A44:A48,"⬜") -> 4 | D9: =COUNTIF('Checklist Production'!A44:A48,"⏳") -> 0 | E9: =COUNTIF('Checklist Production'!A44:A48,"❌") -> 0
A10: Monitoring | B10: =COUNTIF('Checklist Production'!A50:A53,"✅") -> 2 | C10: =COUNTIF('Checklist Production'!A50:A53,"⬜") -> 2 | D10: =COUNTIF('Checklist Production'!A50:A53,"⏳") -> 0 | E10: =COUNTIF('Checklist Production'!A50:A53,"❌") -> 0
A11: Analytics & SEO | B11: =COUNTIF('Checklist Production'!A55:A58,"✅") -> 0 | C11: =COUNTIF('Checklist Production'!A55:A58,"⬜") -> 3 | D11: =COUNTIF('Checklist Production'!A55:A58,"⏳") -> 0 | E11: =COUNTIF('Checklist Production'!A55:A58,"❌") -> 0
A12: Legal | B12: =COUNTIF('Checklist Production'!A60:A63,"✅") -> 0 | C12: =COUNTIF('Checklist Production'!A60:A63,"⬜") -> 3 | D12: =COUNTIF('Checklist Production'!A60:A63,"⏳") -> 0 | E12: =COUNTIF('Checklist Production'!A60:A63,"❌") -> 0
A13: Tests E2E | B13: =COUNTIF('Checklist Production'!A65:A74,"✅") -> 0 | C13: =COUNTIF('Checklist Production'!A65:A74,"⬜") -> 8 | D13: =COUNTIF('Checklist Production'!A65:A74,"⏳") -> 0 | E13: =COUNTIF('Checklist Production'!A65:A74,"❌") -> 0
A14: Lancement | B14: =COUNTIF('Checklist Production'!A76:A80,"✅") -> 0 | C14: =COUNTIF('Checklist Production'!A76:A80,"⬜") -> 5 | D14: =COUNTIF('Checklist Production'!A76:A80,"⏳") -> 0 | E14: =COUNTIF('Checklist Production'!A76:A80,"❌") -> 0
A15: TOTAL | B15: =SUM(B3:B14) -> 23 | C15: =SUM(C3:C14) -> 32 | D15: =SUM(D3:D14) -> 0 | E15: =SUM(E3:E14) -> 2
